Workbook

Sheet Read me
A1: FY2026 R&D Budget, Forecast and Accruals Workbook
A2: Loblolly Ridge Therapeutics
A3: Effective date | B3: 2026-09-15
A4: Purpose | B4: Monthly actuals, accruals and budget through August 2026, the FY reforecast by program and cost category, and supporting purchase-order detail.
A5: Coverage | B5: See each dataset dictionary and summary. Missing numeric values are excluded, not zero.
A6: Summary interpretation | B6: Descriptive statistics of selected records only. Totals of percentages and adjustment values are not operating KPIs.
A7: Introduction | B7: Working R&D budget file after the August 2026 close. Actuals and accruals run from January to August 2026; the full-year view uses the H2 reforecast the executive team approved on September 11, 2026. Prepared by the Controller for budget holders and the CFO.
A8: Sheets | B8: Data 1 – monthly R&D expense, budget, accrued and invoiced amounts by cost object and cost category, January to August 2026 (448 rows: 8 months, 8 cost objects, 7 categories).
A9: Sheets | B9: Data 2 – FY2026 approved budget, January–August actual, September–December reforecast and full-year forecast for all 56 cost object and category cells.
A10: Sheets | B10: Data 3 – research purchase-order lines raised January to August 2026.
A11: Sheets | B11: Summary – formula totals of each numeric column, recalculated on save.
A12: Definitions | B12: Actual expense includes accruals. Accrued is the part of a month's expense not yet invoiced at close; invoiced is the part matched to partner invoices. Monthly variance is actual minus budget; full-year variance is forecast minus budget, so a positive number is an overspend.
A13: Definitions | B13: Budgets are held by cost object (program, discovery, platform and lab, R&D support and quality, and the unallocated reserve) and by seven categories: clinical CRO and sites, clinical pass-through, nonclinical CRO, CMC and clinical supply, research services and consumables, allocated personnel, and consultants and other.
A14: How the numbers are estimated | B14: The close runs to working day 5: partner activity reports are due by working day 3, program owners confirm estimates by working day 4 and the Controller signs off on working day 5. CRO services accrue from activity reports and milestones, pass-through from CRO visit estimates, GLP studies by percentage of completion, CDMO work by batch stage, fixed-fee services straight-line and purchase orders on goods receipt.
... A22: Not included | B22: G&A budget detail, payroll detail, partner invoice images and the cash forecast.

Sheet Summary
A1: Dataset | B1: Measure | C1: Unit | D1: Total | E1: Mean | F1: Records | G1: Period start | H1: Period end
A2: R&D actuals, budget and accruals by month | B2: actual_usd | C2: USD | D2: =SUM('Data 1'!B2:B449) -> 59508220 | E2: =IF(COUNT('Data 1'!B2:B449)=0,0,AVERAGE('Data 1'!B2:B449)) -> 132830.85 | F2: =COUNT('Data 1'!B2:B449) -> 448 | G2: 2026-01-01 | H2: 2026-08-31
A3: R&D actuals, budget and accruals by month | B3: budget_usd | C3: USD | D3: =SUM('Data 1'!F2:F449) -> 64437193 | E3: =IF(COUNT('Data 1'!F2:F449)=0,0,AVERAGE('Data 1'!F2:F449)) -> 143833.02 | F3: =COUNT('Data 1'!F2:F449) -> 448 | G3: 2026-01-01 | H3: 2026-08-31
A4: R&D actuals, budget and accruals by month | B4: accrued_usd | C4: USD | D4: =SUM('Data 1'!G2:G449) -> 14096246 | E4: =IF(COUNT('Data 1'!G2:G449)=0,0,AVERAGE('Data 1'!G2:G449)) -> 31464.835 | F4: =COUNT('Data 1'!G2:G449) -> 448 | G4: 2026-01-01 | H4: 2026-08-31
A5: R&D actuals, budget and accruals by month | B5: invoiced_usd | C5: USD | D5: =SUM('Data 1'!H2:H449) -> 45411974 | E5: =IF(COUNT('Data 1'!H2:H449)=0,0,AVERAGE('Data 1'!H2:H449)) -> 101366.01 | F5: =COUNT('Data 1'!H2:H449) -> 448 | G5: 2026-01-01 | H5: 2026-08-31
A6: R&D actuals, budget and accruals by month | B6: variance_usd | C6: USD | D6: =SUM('Data 1'!I2:I449) -> -4928973 | E6: =IF(COUNT('Data 1'!I2:I449)=0,0,AVERAGE('Data 1'!I2:I449)) -> -11002.172 | F6: =COUNT('Data 1'!I2:I449) -> 448 | G6: 2026-01-01 | H6: 2026-08-31
A7: FY2026 budget and reforecast | B7: fy_budget_usd | C7: USD | D7: =SUM('Data 2'!B2:B57) -> 94800000 | E7: =IF(COUNT('Data 2'!B2:B57)=0,0,AVERAGE('Data 2'!B2:B57)) -> 1692857.1 | F7: =COUNT('Data 2'!B2:B57) -> 56 | G7: 2026-01-01 | H7: 2026-09-11
A8: FY2026 budget and reforecast | B8: ytd_actual_usd | C8: USD | D8: =SUM('Data 2'!E2:E57) -> 59508220 | E8: =IF(COUNT('Data 2'!E2:E57)=0,0,AVERAGE('Data 2'!E2:E57)) -> 1062646.8 | F8: =COUNT('Data 2'!E2:E57) -> 56 | G8: 2026-01-01 | H8: 2026-09-11
A9: FY2026 budget and reforecast | B9: h2_reforecast_usd | C9: USD | D9: =SUM('Data 2'!F2:F57) -> 35561780 | E9: =IF(COUNT('Data 2'!F2:F57)=0,0,AVERAGE('Data 2'!F2:F57)) -> 635031.79 | F9: =COUNT('Data 2'!F2:F57) -> 56 | G9: 2026-01-01 | H9: 2026-09-11
A10: FY2026 budget and reforecast | B10: fy_forecast_usd | C10: USD | D10: =SUM('Data 2'!G2:G57) -> 95070000 | E10: =IF(COUNT('Data 2'!G2:G57)=0,0,AVERAGE('Data 2'!G2:G57)) -> 1697678.6 | F10: =COUNT('Data 2'!G2:G57) -> 56 | G10: 2026-01-01 | H10: 2026-09-11
A11: FY2026 budget and reforecast | B11: variance_to_budget_usd | C11: USD | D11: =SUM('Data 2'!H2:H57) -> 270000 | E11: =IF(COUNT('Data 2'!H2:H57)=0,0,AVERAGE('Data 2'!H2:H57)) -> 4821.4286 | F11: =COUNT('Data 2'!H2:H57) -> 56 | G11: 2026-01-01 | H11: 2026-09-11
A12: Research purchase-order lines | B12: amount_usd | C12: USD | D12: =SUM('Data 3'!B2:B1115) -> 2238490 | E12: =IF(COUNT('Data 3'!B2:B1115)=0,0,AVERAGE('Data 3'!B2:B1115)) -> 2009.4165 | F12: =COUNT('Data 3'!B2:B1115) -> 1114 | G12: 2026-01-01 | H12: 2026-08-31

Sheet Dictionary
A1: Dataset | B1: Field | C1: Definition | D1: Unit | E1: Type | F1: Reference
A2: R&D actuals, budget and accruals by month | B2: record_id | C2: Record id | E2: id
A3: R&D actuals, budget and accruals by month | B3: actual_usd | C3: Actual expense including accruals | D3: USD | E3: number
A4: R&D actuals, budget and accruals by month | B4: cost_object | C4: Cost object | E4: category
A5: R&D actuals, budget and accruals by month | B5: cost_category | C5: Cost category | E5: category
A6: R&D actuals, budget and accruals by month | B6: month_start | C6: Month start | E6: date
A7: R&D actuals, budget and accruals by month | B7: budget_usd | C7: Approved budget phased to the month | D7: USD | E7: number
A8: R&D actuals, budget and accruals by month | B8: accrued_usd | C8: Unbilled part of actual at month end | D8: USD | E8: number
A9: R&D actuals, budget and accruals by month | B9: invoiced_usd | C9: Actual minus accrued | D9: USD | E9: number
A10: R&D actuals, budget and accruals by month | B10: variance_usd | C10: Actual minus budget | D10: USD | E10: number
A11: FY2026 budget and reforecast | B11: record_id | C11: Record id | E11: id
A12: FY2026 budget and reforecast | B12: fy_budget_usd | C12: Approved FY2026 budget | D12: USD | E12: number
A13: FY2026 budget and reforecast | B13: cost_object | C13: Cost object | E13: category
A14: FY2026 budget and reforecast | B14: cost_category | C14: Cost category | E14: category
A15: FY2026 budget and reforecast | B15: ytd_actual_usd | C15: January-August actual | D15: USD | E15: number
A16: FY2026 budget and reforecast | B16: h2_reforecast_usd | C16: September-December reforecast | D16: USD | E16: number
A17: FY2026 budget and reforecast | B17: fy_forecast_usd | C17: YTD actual plus H2 reforecast | D17: USD | E17: number
A18: FY2026 budget and reforecast | B18: variance_to_budget_usd | C18: FY forecast minus FY budget | D18: USD | E18: number
A19: Research purchase-order lines | B19: po_line_id | C19: Po line id | E19: id
A20: Research purchase-order lines | B20: amount_usd | C20: Amount | D20: USD | E20: number
A21: Research purchase-order lines | B21: po_number | C21: Po number | E21: category
A22: Research purchase-order lines | B22: supplier | C22: Supplier | E22: category
A23: Research purchase-order lines | B23: category | C23: Category | E23: category
A24: Research purchase-order lines | B24: cost_object | C24: Cost object | E24: category
A25: Research purchase-order lines | B25: order_date | C25: Order date | E25: date
A26: Research purchase-order lines | B26: receipt_date | C26: Receipt date | E26: date
A27: Research purchase-order lines | B27: invoice_match | C27: Invoice match | E27: category
A28: Research purchase-order lines | B28: status | C28: Status | E28: category

Sheet Data 1
A1: record_id | B1: actual_usd | C1: cost_object | D1: cost_category | E1: month_start | F1: budget_usd | G1: accrued_usd | H1: invoiced_usd | I1: variance_usd
A2: RM-0001 | B2: 1996846 | C2: LRT-1107 | D2: clinical CRO & sites | E2: 2026-01-01 | F2: 1947333 | G2: 792285.82 | H2: 1204560.2 | I2: 49513
A3: RM-0002 | B3: 2303398 | C3: LRT-1107 | D3: clinical CRO & sites | E3: 2026-02-01 | F3: 2010833 | G3: 763915.67 | H3: 1539482.3 | I3: 292565
A4: RM-0003 | B4: 1904816 | C4: LRT-1107 | D4: clinical CRO & sites | E4: 2026-03-01 | F4: 2074333 | G4: 729623.47 | H4: 1175192.5 | I4: -169517
A5: RM-0004 | B5: 2085813 | C5: LRT-1107 | D5: clinical CRO & sites | E5: 2026-04-01 | F5: 2116667 | G5: 865348.54 | H5: 1220464.5 | I5: -30854
A6: RM-0005 | B6: 2096519 | C6: LRT-1107 | D6: clinical CRO & sites | E6: 2026-05-01 | F6: 2159000 | G6: 828208.75 | H6: 1268310.2 | I6: -62481
A7: RM-0006 | B7: 2172751 | C7: LRT-1107 | D7: clinical CRO & sites | E7: 2026-06-01 | F7: 2222500 | G7: 963428.26 | H7: 1209322.7 | I7: -49749
A8: RM-0007 | B8: 2066151 | C8: LRT-1107 | D8: clinical CRO & sites | E8: 2026-07-01 | F8: 2243667 | G8: 733438.12 | H8: 1332712.9 | I8: -177516
A9: RM-0008 | B9: 2205706 | C9: LRT-1107 | D9: clinical CRO & sites | E9: 2026-08-01 | F9: 2201334 | G9: 1047710.3 | H9: 1157995.6 | I9: 4372
A10: RM-0009 | B10: 932635 | C10: LRT-1107 | D10: clinical pass-through | E10: 2026-01-01 | F10: 961379 | G10: 350962.02 | H10: 581672.98 | I10: -28744
A11: RM-0010 | B11: 1282300 | C11: LRT-1107 | D11: clinical pass-through | E11: 2026-02-01 | F11: 1300690 | G11: 589599.07 | H11: 692700.93 | I11: -18390
A12: RM-0011 | B12: 800629 | C12: LRT-1107 | D12: clinical pass-through | E12: 2026-03-01 | F12: 876552 | G12: 294095.22 | H12: 506533.78 | I12: -75923
A13: RM-0012 | B13: 1118584 | C13: LRT-1107 | D13: clinical pass-through | E13: 2026-04-01 | F13: 1272414 | G13: 577043.47 | H13: 541540.53 | I13: -153830
... A449: RM-0448 | B449: 0 | C449: Unallocated reserve | D449: consultants & other | E449: 2026-08-01 | F449: 220000 | G449: 0 | H449: 0 | I449: -220000

Sheet Data 2
A1: record_id | B1: fy_budget_usd | C1: cost_object | D1: cost_category | E1: ytd_actual_usd | F1: h2_reforecast_usd | G1: fy_forecast_usd | H1: variance_to_budget_usd
A2: FY-001 | B2: 25400000 | C2: LRT-1107 | D2: clinical CRO & sites | E2: 16832000 | F2: 9468000 | G2: 26300000 | H2: 900000
A3: FY-002 | B3: 12300000 | C3: LRT-1107 | D3: clinical pass-through | E3: 8479000 | F3: 5421000 | G3: 13900000 | H3: 1600000
A4: FY-003 | B4: 300000 | C4: LRT-1107 | D4: nonclinical CRO | E4: 210000 | F4: 90000 | G4: 300000 | H4: 0
A5: FY-004 | B5: 4920000 | C5: LRT-1107 | D5: CMC & clinical supply | E5: 2760800 | F5: 1999200 | G5: 4760000 | H5: -160000
A6: FY-005 | B6: 450000 | C6: LRT-1107 | D6: research services & consumables | E6: 316800 | F6: 163200 | G6: 480000 | H6: 30000
A7: FY-006 | B7: 7300000 | C7: LRT-1107 | D7: personnel (allocated) | E7: 4835750 | F7: 2414250 | G7: 7250000 | H7: -50000
A8: FY-007 | B8: 1930000 | C8: LRT-1107 | D8: consultants & other | E8: 1236000 | F8: 824000 | G8: 2060000 | H8: 130000
A9: FY-008 | B9: 1050000 | C9: LRT-2240 | D9: clinical CRO & sites | E9: 985800 | F9: 74200 | G9: 1060000 | H9: 10000
A10: FY-009 | B10: 270000 | C10: LRT-2240 | D10: clinical pass-through | E10: 247000 | F10: 13000 | G10: 260000 | H10: -10000
A11: FY-010 | B11: 90000 | C11: LRT-2240 | D11: nonclinical CRO | E11: 60000 | F11: 0 | G11: 60000 | H11: -30000
A12: FY-011 | B12: 880000 | C12: LRT-2240 | D12: CMC & clinical supply | E12: 390000 | F12: 130000 | G12: 520000 | H12: -360000
A13: FY-012 | B13: 60000 | C13: LRT-2240 | D13: research services & consumables | E13: 32000 | F13: 8000 | G13: 40000 | H13: -20000
... A57: FY-056 | B57: 2400000 | C57: Unallocated reserve | D57: consultants & other | E57: 0 | F57: 1150000 | G57: 1150000 | H57: -1250000

Sheet Data 3
A1: po_line_id | B1: amount_usd | C1: po_number | D1: supplier | E1: category | F1: cost_object | G1: order_date | H1: receipt_date | I1: invoice_match | J1: status
A2: POL-00001 | B2: 229.44 | C2: PO-26001 | D2: Lonestar Reagents | E2: lab consumables | F2: Platform & lab | G2: 2026-01-01 | H2: 2026-01-09 | I2: matched | J2: received
A3: POL-00002 | B3: 438.13 | C3: PO-26001 | D3: Cypress Scientific Supply | E3: lab consumables | F3: Platform & lab | G3: 2026-01-01 | H3: 2026-01-10 | I3: matched | J3: received
A4: POL-00003 | B4: 605.08 | C4: PO-26002 | D4: Cypress Scientific Supply | E4: reagents & kits | F4: Platform & lab | G4: 2026-01-01 | H4: 2026-01-14 | I4: matched | J4: received
A5: POL-00004 | B5: 4409.79 | C5: PO-26002 | D5: Brazoria Lab Equipment Services | E5: small equipment | F5: Platform & lab | G5: 2026-01-01 | H5: 2026-01-25 | I5: matched | J5: received
A6: POL-00005 | B6: 3190.11 | C6: PO-26002 | D6: Brazoria Lab Equipment Services | E6: small equipment | F6: Platform & lab | G6: 2026-01-01 | H6: 2026-02-07 | I6: matched | J6: received
A7: POL-00006 | B7: 1312.1 | C7: PO-26003 | D7: Cypress Scientific Supply | E7: lab consumables | F7: Discovery | G7: 2026-01-02 | H7: 2026-01-09 | I7: matched | J7: received
A8: POL-00007 | B8: 421.57 | C8: PO-26003 | D8: Cypress Scientific Supply | E8: lab consumables | F8: Platform & lab | G8: 2026-01-02 | H8: 2026-01-09 | I8: matched | J8: received
A9: POL-00008 | B9: 523.55 | C9: PO-26003 | D9: Cypress Scientific Supply | E9: lab consumables | F9: Platform & lab | G9: 2026-01-02 | H9: 2026-01-11 | I9: matched | J9: received
A10: POL-00009 | B10: 1407.07 | C10: PO-26004 | D10: ColdTrace Monitoring | E10: EHS services | F10: Discovery | G10: 2026-01-05 | H10: 2026-01-11 | I10: matched | J10: received
A11: POL-00010 | B11: 599.98 | C11: PO-26004 | D11: ColdTrace Monitoring | E11: EHS services | F11: Discovery | G11: 2026-01-05 | H11: 2026-01-13 | I11: matched | J11: received
A12: POL-00011 | B12: 420.37 | C12: PO-26005 | D12: Cypress Scientific Supply | E12: lab consumables | F12: Discovery | G12: 2026-01-05 | H12: 2026-01-12 | I12: matched | J12: received
A13: POL-00012 | B13: 319.17 | C13: PO-26006 | D13: Cypress Scientific Supply | E13: lab consumables | F13: Discovery | G13: 2026-01-05 | H13: 2026-01-07 | I13: matched | J13: received
... A278: POL-00277 | B278: 848.63 | C278: PO-26147 | D278: Cypress Scientific Supply | E278: lab consumables | F278: Discovery | G278: 2026-03-09 | H278: 2026-03-13 | I278: matched | J278: received
A279: POL-00278 | B279: 332.84 | C279: PO-26148 | D279: Lonestar Reagents | E279: lab consumables | F279: Discovery | G279: 2026-03-09 | I279: matched | J279: cancelled
A280: POL-00279 | B280: 555.42 | C280: PO-26149 | D280: Lonestar Reagents | E280: lab consumables | F280: Discovery | G280: 2026-03-09 | H280: 2026-03-16 | I280: matched | J280: received
A281: POL-00280 | B281: 6209.96 | C281: PO-26149 | D281: Notewell Scientific Software | E281: lab software | F281: Discovery | G281: 2026-03-09 | H281: 2026-03-13 | I281: matched | J281: received
A282: POL-00281 | B282: 212.26 | C282: PO-26150 | D282: Cypress Scientific Supply | E282: reagents & kits | F282: Discovery | G282: 2026-03-09 | H282: 2026-03-14 | I282: matched | J282: received
A283: POL-00282 | B283: 401.91 | C283: PO-26150 | D283: Lonestar Reagents | E283: reagents & kits | F283: Discovery | G283: 2026-03-09 | H283: 2026-03-23 | I283: matched | J283: received
A284: POL-00283 | B284: 714.15 | C284: PO-26150 | D284: Lonestar Reagents | E284: reagents & kits | F284: Discovery | G284: 2026-03-09 | H284: 2026-03-17 | I284: matched | J284: received
A285: POL-00284 | B285: 5488.1 | C285: PO-26150 | D285: Brazoria Lab Equipment Services | E285: small equipment | F285: Discovery | G285: 2026-03-09 | H285: 2026-04-17 | I285: matched | J285: received
A286: POL-00285 | B286: 9851.37 | C286: PO-26150 | D286: Brazoria Lab Equipment Services | E286: small equipment | F286: Discovery | G286: 2026-03-09 | H286: 2026-04-03 | I286: matched | J286: received
A287: POL-00286 | B287: 35142.61 | C287: PO-26151 | D287: Brazoria Lab Equipment Services | E287: small equipment | F287: Discovery | G287: 2026-03-09 | H287: 2026-03-31 | I287: matched | J287: received
A288: POL-00287 | B288: 4019.33 | C288: PO-26152 | D288: Lonestar Reagents | E288: lab consumables | F288: LRT-1107 | G288: 2026-03-09 | H288: 2026-03-16 | I288: matched | J288: received
A289: POL-00288 | B289: 192.65 | C289: PO-26153 | D289: Cypress Scientific Supply | E289: lab consumables | F289: Platform & lab | G289: 2026-03-09 | I289: matched | J289: cancelled
A290: POL-00289 | B290: 1578.57 | C290: PO-26154 | D290: Lonestar Reagents | E290: lab consumables | F290: Platform & lab | G290: 2026-03-09 | H290: 2026-03-13 | I290: matched | J290: received
A291: POL-00290 | B291: 1744.65 | C291: PO-26154 | D291: Lonestar Reagents | E291: lab consumables | F291: Platform & lab | G291: 2026-03-09 | H291: 2026-03-16 | I291: matched | J291: received
A292: POL-00291 | B292: 377.06 | C292: PO-26155 | D292: Lonestar Reagents | E292: lab consumables | F292: Platform & lab | G292: 2026-03-09 | H292: 2026-03-11 | I292: matched | J292: received
A293: POL-00292 | B293: 2085.65 | C293: PO-26156 | D293: Notewell Scientific Software | E293: lab software | F293: Platform & lab | G293: 2026-03-09 | H293: 2026-03-11 | I293: matched | J293: received
A294: POL-00293 | B294: 6070.54 | C294: PO-26156 | D294: Cypress Scientific Supply | E294: reagents & kits | F294: Platform & lab | G294: 2026-03-09 | H294: 2026-03-23 | I294: matched | J294: received
A295: POL-00294 | B295: 321.46 | C295: PO-26156 | D295: Cypress Scientific Supply | E295: reagents & kits | F295: Platform & lab | G295: 2026-03-09 | H295: 2026-03-18 | I295: matched | J295: received
A296: POL-00295 | B296: 1601.66 | C296: PO-26156 | D296: ColdTrace Monitoring | E296: EHS services | F296: Discovery | G296: 2026-03-10 | H296: 2026-03-12 | I296: matched | J296: received
A297: POL-00296 | B297: 92.32 | C297: PO-26156 | D297: Lonestar Reagents | E297: lab consumables | F297: Discovery | G297: 2026-03-10 | H297: 2026-03-15 | I297: matched | J297: received
A298: POL-00297 | B298: 468.53 | C298: PO-26156 | D298: Cypress Scientific Supply | E298: lab consumables | F298: Discovery | G298: 2026-03-10 | H298: 2026-03-18 | I298: matched | J298: received
A299: POL-00298 | B299: 354.28 | C299: PO-26156 | D299: Lonestar Reagents | E299: lab consumables | F299: Platform & lab | G299: 2026-03-10 | H299: 2026-03-19 | I299: matched | J299: received
A300: POL-00299 | B300: 440.93 | C300: PO-26156 | D300: Cypress Scientific Supply | E300: lab consumables | F300: Discovery | G300: 2026-03-11 | H300: 2026-03-15 | I300: matched | J300: received
A301: POL-00300 | B301: 562.05 | C301: PO-26157 | D301: Cypress Scientific Supply | E301: lab consumables | F301: Discovery | G301: 2026-03-11 | H301: 2026-03-19 | I301: matched | J301: received
... A527: POL-00526 | B527: 1533.43 | C527: PO-26280 | D527: Lonestar Reagents | E527: reagents & kits | F527: Discovery | G527: 2026-04-23 | H527: 2026-04-26 | I527: matched | J527: received
A528: POL-00527 | B528: 665.12 | C528: PO-26280 | D528: ColdTrace Monitoring | E528: instrument service | F528: Platform & lab | G528: 2026-04-23 | I528: matched | J528: cancelled
A529: POL-00528 | B529: 107.95 | C529: PO-26281 | D529: Lonestar Reagents | E529: lab consumables | F529: Platform & lab | G529: 2026-04-23 | H529: 2026-05-02 | I529: matched | J529: received
...
